Workbook
Name Aporte: 'Planilha Cenários'!$D$13
Name patrim_acum: 'Planilha Cenários'!$D$16
Name prazo_investimento: 'Planilha Cenários'!$D$14
Name Rendimento_Carteira: 'Planilha Cenários'!#REF!
Name rentabilidade: 'Planilha Cenários'!$D$15
Name Salario: 'Planilha Cenários'!$D$7
Name Sugest_invest: 'Planilha Cenários'!$D$8

Sheet Planilha Cenários
A1: . | B1: . | C1: . | D1: . | E1: . | F1: . | G1: . | H1: . | I1: . | J1: . | K1: . | L1: .
L2: .
C3: $$$$$ AFX INVEST $$$$$ | L3: .
L4: .
C5: 1- Informe abaixo seu salário líquido para ter a sugestão de investimentos: | L5: .
C6: Configurações | L6: .
C7: Salário Líquido | D7: 5000 | L7: .
C8: Sugestão de Investimento | D8: =Salario*0.225 -> 1125 | L8: .
L9: .
C10: 2- Informe nos campos em branco abaixo quanto deseja aportar, por quanto tempo e a taxa de rendimentos mensal desejada. | L10: .
C11: Obs: Sugerimos que use a taxa da Selic ou uma alguma taxa histórica que busque se aproximar da realidade. | L11: .
C12: APORTES MENSAIS | L12: .
C13: Quanto investir por mês ? | D13: 500 | L13: .
C14: Por quantos anos ? | D14: 5 | L14: .
C15: Qual a taxa de rendimento mensal ? | D15: 0.01079 | L15: .
C16: Quanto de patrimônio vai acumular ? | D16: =-FV(rentabilidade,prazo_investimento*12,Aporte) -> 41888.457 | L16: .
C17: Quanto vai receber de dividendos por mês ? | D17: =patrim_acum*rentabilidade -> 451.97645 | L17: .
L18: .
C19: 3- Com base nas informações inseridas no quadro acima, veja uma projeção de quanto vai acumular e receber ao longo dos anos projetados. | L19: .
C20: SIMULAÇÃO DE CENÁRIOS | E20: DIVIDENDOS MENSAIS | L20: .
A21: 2 | C21: Qual vai ser meu patrimonio daqui 2 anos? | D21: =-FV(rentabilidade,(A21*12),Aporte) -> 13613.814 | E21: =D21*rentabilidade -> 146.89305 | L21: .
A22: 5 | C22: Qual vai ser meu patrimonio daqui 5 anos? | D22: =-FV(rentabilidade,(A22*12),Aporte) -> 41888.457 | E22: =D22*rentabilidade -> 451.97645 | L22: .
A23: 10 | C23: Qual vai ser meu patrimonio daqui 10 anos? | D23: =-FV(rentabilidade,(A23*12),Aporte) -> 121642.11 | E23: =D23*rentabilidade -> 1312.5183 | L23: .
A24: 20 | C24: Qual vai ser meu patrimonio daqui 20 anos? | D24: =-FV(rentabilidade,(A24*12),Aporte) -> 562599.2 | E24: =D24*rentabilidade -> 6070.4454 | L24: .
A25: 30 | C25: Qual vai ser meu patrimonio daqui 30 anos? | D25: =-FV(rentabilidade,(A25*12),Aporte) -> 2161084.8 | E25: =D25*rentabilidade -> 23318.105 | L25: .
L26: .
C27: Clique no campo indicado pela seta ao lado e escolha o que se encaixa melhor no seu perfil de investidor: | G27: CARTEIRA RECOMENDADA COM BASE NO PERFIL ESCOLHIDO | L27: .
L28: .
C29: Tipo de Perfil do Investidor | D29: Moderado | L29: .
C30: Valor a ser aportado mesalmente | D30: =Aporte -> 500 | L30: .
L31: .
C32: Tipos de Investimento | D32: % Sugerido | E32: Valores | L32: .
C33: Renda Fixa | D33: =VLOOKUP(CONCATENATE($D$29," - ",C33),'Planilha de Apoio'!B:E,4,0) -> 0.35 | E33: =$D$30*D33 -> 175 | L33: .
C34: Ações | D34: =VLOOKUP(CONCATENATE($D$29," - ",C34),'Planilha de Apoio'!B:E,4,0) -> 0.3 | E34: =$D$30*D34 -> 150 | L34: .
C35: FII's | D35: =VLOOKUP(CONCATENATE($D$29," - ",C35),'Planilha de Apoio'!B:E,4,0) -> 0.15 | E35: =$D$30*D35 -> 75 | L35: .
C36: Criptomoedas | D36: =VLOOKUP(CONCATENATE($D$29," - ",C36),'Planilha de Apoio'!B:E,4,0) -> 0.05 | E36: =$D$30*D36 -> 25 | L36: .
C37: Ações Estrangeiras | D37: =VLOOKUP(CONCATENATE($D$29," - ",C37),'Planilha de Apoio'!B:E,4,0) -> 0.1 | E37: =$D$30*D37 -> 50 | L37: .
C38: ETF's | D38: =VLOOKUP(CONCATENATE($D$29," - ",C38),'Planilha de Apoio'!B:E,4,0) -> 0.05 | E38: =$D$30*D38 -> 25 | L38: .
C39: TOTAL | D39: =SUM(D33:D38) -> 1 | E39: =SUM(E33:E38) -> 500 | L39: .
L40: .
...

Sheet Monte Sua Carteira
B2: $$$$$ AFX INVEST $$$$$
B4: MONTE SUA PLANILHA !
B6: 1- INSIRA AS INFORMAÇÕES DE SUAS COMPRAS REALIZADAS NOS CAMPOS "INVESTIMENTO REALIZADO", "QUANTIDADE" E "PREÇO UNITÁRIO"
B7: 2- VERIFIQUE SE O TOTAL INVESTIDO ESTÁ BATENDO CONFORME QUADRO ''TOTAL INVESTIDO''
B8: 3- COMPARE SE A SUA DISTRIBUIÇÃO EM CARTEIRA ESTÁ DE ACORDO COM O SEU PERFIL DE INVESTIDOR NA ABA "PLANILHA CENÁRIOS".
B9: OBS1: QUANDO SE TRATAR DE UM APORTE DE RENDA FIXA, COLOQUE NO CAMPO DE VALOR UNITÁRIO SEMPRE 1.
B10: OBS2: VOCÊ NÃO PRECISA SEGUIR A RISCA O PERFIL DE INVESTIDOR, É APENAS UMA SUGESTÃO.
B11: OBS3: CASO O ATIVO COMPRADO NÃO ESTEJA APARECENDO NA COLUNA "INVESTIMENTO REALIZADO", VOCÊ PODE INCLUÍ-LO NA ABA DA "PLANILHA DE APOIO".
B13: Investimento Realizado | C13: Tipo de Investimento | D13: Quantidade | E13: Preço Unitário | F13: Valor Total | H13: SUA CARTEIRA DE INVESTIMENTOS | P13: Tipo de Investimento | Q13: TOTAL
B14: POMO4 | C14: =VLOOKUP(B14,'Planilha de Apoio'!G:H,2,0) -> Ações | D14: 400 | E14: 5.65 | F14: =D14*E14 -> 2260 | P14: Renda Fixa | Q14: =SUMIF(C:F,P14,F:F) -> 15000
B15: CSNA3 | C15: =VLOOKUP(B15,'Planilha de Apoio'!G:H,2,0) -> Ações | D15: 200 | E15: 6.27 | F15: =D15*E15 -> 1254 | P15: Ações | Q15: =SUMIF(C:F,P15,F:F) -> 4649
B16: RECV3 | C16: =VLOOKUP(B16,'Planilha de Apoio'!G:H,2,0) -> Ações | D16: 100 | E16: 11.35 | F16: =D16*E16 -> 1135 | P16: FII's | Q16: =SUMIF(C:F,P16,F:F) -> 4123.2
B17: GGRC11 | C17: =VLOOKUP(B17,'Planilha de Apoio'!G:H,2,0) -> FII's | D17: 270 | E17: 9.76 | F17: =D17*E17 -> 2635.2 | P17: Criptomoedas | Q17: =SUMIF(C:F,P17,F:F) -> 4500
B18: CPTS11 | C18: =VLOOKUP(B18,'Planilha de Apoio'!G:H,2,0) -> FII's | D18: 200 | E18: 7.44 | F18: =D18*E18 -> 1488 | P18: Ações Estrangeiras | Q18: =SUMIF(C:F,P18,F:F) -> 6250
B19: COIN11 | C19: =VLOOKUP(B19,'Planilha de Apoio'!G:H,2,0) -> ETF's | D19: 30 | E19: 43.1 | F19: =D19*E19 -> 1293 | P19: ETF's | Q19: =SUMIF(C:F,P19,F:F) -> 2453.6
B20: ETHY11 | C20: =VLOOKUP(B20,'Planilha de Apoio'!G:H,2,0) -> ETF's | D20: 20 | E20: 58.03 | F20: =D20*E20 -> 1160.6 | P20: TOTAL INVESTIDO | Q20: =SUM(Q14:Q19) -> 36975.8
B21: CDB | C21: =VLOOKUP(B21,'Planilha de Apoio'!G:H,2,0) -> Renda Fixa | D21: 1 | E21: 15000 | F21: =D21*E21 -> 15000
B22: BTC | C22: =VLOOKUP(B22,'Planilha de Apoio'!G:H,2,0) -> Criptomoedas | D22: 0.01 | E22: 200000 | F22: =D22*E22 -> 2000
B23: BNB | C23: =VLOOKUP(B23,'Planilha de Apoio'!G:H,2,0) -> Criptomoedas | D23: 0.2 | E23: 5000 | F23: =D23*E23 -> 1000
B24: ETH | C24: =VLOOKUP(B24,'Planilha de Apoio'!G:H,2,0) -> Criptomoedas | D24: 0.1 | E24: 15000 | F24: =D24*E24 -> 1500
B25: AMZO34 | C25: =VLOOKUP(B25,'Planilha de Apoio'!G:H,2,0) -> Ações Estrangeiras | D25: 25 | E25: 250 | F25: =D25*E25 -> 6250
C26: =VLOOKUP(B26,'Planilha de Apoio'!G:H,2,0) -> #N/A | F26: =D26*E26 -> 0
C27: =VLOOKUP(B27,'Planilha de Apoio'!G:H,2,0) -> #N/A | F27: =D27*E27 -> 0
C28: =VLOOKUP(B28,'Planilha de Apoio'!G:H,2,0) -> #N/A | F28: =D28*E28 -> 0
C29: =VLOOKUP(B29,'Planilha de Apoio'!G:H,2,0) -> #N/A | F29: =D29*E29 -> 0
C30: =VLOOKUP(B30,'Planilha de Apoio'!G:H,2,0) -> #N/A | F30: =D30*E30 -> 0
C31: =VLOOKUP(B31,'Planilha de Apoio'!G:H,2,0) -> #N/A | F31: =D31*E31 -> 0 | H31: CARTEIRA RECOMENDADA COM BASE NO PERFIL ESCOLHIDO
C32: =VLOOKUP(B32,'Planilha de Apoio'!G:H,2,0) -> #N/A | F32: =D32*E32 -> 0
C33: =VLOOKUP(B33,'Planilha de Apoio'!G:H,2,0) -> #N/A | F33: =D33*E33 -> 0
C34: =VLOOKUP(B34,'Planilha de Apoio'!G:H,2,0) -> #N/A | F34: =D34*E34 -> 0
C35: =VLOOKUP(B35,'Planilha de Apoio'!G:H,2,0) -> #N/A | F35: =D35*E35 -> 0
C36: =VLOOKUP(B36,'Planilha de Apoio'!G:H,2,0) -> #N/A | F36: =D36*E36 -> 0
C37: =VLOOKUP(B37,'Planilha de Apoio'!G:H,2,0) -> #N/A | F37: =D37*E37 -> 0
C38: =VLOOKUP(B38,'Planilha de Apoio'!G:H,2,0) -> #N/A | F38: =D38*E38 -> 0
C39: =VLOOKUP(B39,'Planilha de Apoio'!G:H,2,0) -> #N/A | F39: =D39*E39 -> 0
C40: =VLOOKUP(B40,'Planilha de Apoio'!G:H,2,0) -> #N/A | F40: =D40*E40 -> 0
C41: =VLOOKUP(B41,'Planilha de Apoio'!G:H,2,0) -> #N/A | F41: =D41*E41 -> 0
C42: =VLOOKUP(B42,'Planilha de Apoio'!G:H,2,0) -> #N/A | F42: =D42*E42 -> 0
C43: =VLOOKUP(B43,'Planilha de Apoio'!G:H,2,0) -> #N/A | F43: =D43*E43 -> 0
... C505: =VLOOKUP(B505,'Planilha de Apoio'!G:H,2,0) -> #N/A | F505: =D505*E505 -> 0

Sheet Planilha de Apoio
B2: Chave | C2: Perfil | D2: Tipo de Investimento | E2: Percentual | G2: Código | H2: Tipo de Investimento
B3: =CONCATENATE(C3," - ",D3) -> Conservador - Renda Fixa | C3: Conservador | D3: Renda Fixa | E3: 0.5 | G3: ABCB4 | H3: Ações
B4: =CONCATENATE(C4," - ",D4) -> Conservador - Ações | C4: Conservador | D4: Ações | E4: 0.2 | G4: ABEV3 | H4: Ações
B5: =CONCATENATE(C5," - ",D5) -> Conservador - FII's | C5: Conservador | D5: FII's | E5: 0.1 | G5: AGRO3 | H5: Ações
B6: =CONCATENATE(C6," - ",D6) -> Conservador - Criptomoedas | C6: Conservador | D6: Criptomoedas | E6: 0.05 | G6: ALOS3 | H6: Ações
B7: =CONCATENATE(C7," - ",D7) -> Conservador - Ações Estrangeiras | C7: Conservador | D7: Ações Estrangeiras | E7: 0.1 | G7: ALPA4 | H7: Ações
B8: =CONCATENATE(C8," - ",D8) -> Conservador - ETF's | C8: Conservador | D8: ETF's | E8: 0.05 | G8: AMBP3 | H8: Ações
B9: =CONCATENATE(C9," - ",D9) -> Moderado - Renda Fixa | C9: Moderado | D9: Renda Fixa | E9: 0.35 | G9: ANIM3 | H9: Ações
B10: =CONCATENATE(C10," - ",D10) -> Moderado - Ações | C10: Moderado | D10: Ações | E10: 0.3 | G10: ASAI3 | H10: Ações
B11: =CONCATENATE(C11," - ",D11) -> Moderado - FII's | C11: Moderado | D11: FII's | E11: 0.15 | G11: AURE3 | H11: Ações
B12: =CONCATENATE(C12," - ",D12) -> Moderado - Criptomoedas | C12: Moderado | D12: Criptomoedas | E12: 0.05 | G12: AZUL4 | H12: Ações
B13: =CONCATENATE(C13," - ",D13) -> Moderado - Ações Estrangeiras | C13: Moderado | D13: Ações Estrangeiras | E13: 0.1 | G13: B3SA3 | H13: Ações
B14: =CONCATENATE(C14," - ",D14) -> Moderado - ETF's | C14: Moderado | D14: ETF's | E14: 0.05 | G14: BBAS3 | H14: Ações
... B20: =CONCATENATE(C20," - ",D20) -> Agressivo - ETF's | C20: Agressivo | D20: ETF's | E20: 0.15 | G20: BLAU3 | H20: Ações
G21: BMGB4 | H21: Ações
G22: BPAC11 | H22: Ações
G23: BRAP4 | H23: Ações
G24: BRAV3 | H24: Ações
G25: BRFS3 | H25: Ações
G26: BRKM5 | H26: Ações
G27: CAML3 | H27: Ações
G28: CASH3 | H28: Ações
G29: CBAV3 | H29: Ações
G30: CCRO3 | H30: Ações
G31: CEAB3 | H31: Ações
G32: CMIG4 | H32: Ações
... G198: RDB | H198: Renda Fixa
